Workbook

Sheet Test case
A1: Mã TC | B1: Nhóm chức năng | C1: Tiêu đề | D1: Điều kiện tiên quyết | E1: Ưu tiên | F1: Bước thực hiện | G1: Dữ liệu kiểm thử | H1: Kết quả mong đợi | I1: Kết quả thực tế | J1: Pass/Fail | K1: Mã bug
A2: 56 | B2: Thông tin địa chỉ thanh toán hợp lệ | C2: Hiển thị đầy đủ các trường địa chỉ thanh toán trên trang giỏ hàng | D2: Người dùng đang ở trang giỏ hàng (basket page) và khu vực nhập địa chỉ thanh toán được hiển thị. | E2: High | F2: 1. Quan sát khu vực nhập địa chỉ thanh toán trên trang giỏ hàng. 2. Nhấp lần lượt vào từng trường để kiểm tra có thể focus và nhập liệu. | G2: — | H2: 1. Hiển thị đầy đủ các trường: First name, Last name, Email, Address, Postcode. 2. Mỗi trường đều có thể focus và sẵn sàng nhận dữ liệu nhập. | I2: Đúng như kết quả mong đợi | J2: Pass
A3: 57 | B3: Thông tin địa chỉ thanh toán hợp lệ | C3: Nhập dữ liệu hợp lệ cho tất cả trường và không hiển thị lỗi | D3: Người dùng đang ở trang giỏ hàng và form địa chỉ thanh toán đang trống hoặc có thể chỉnh sửa. | E3: High | F3: 1. Nhập First name hợp lệ. 2. Nhập Last name hợp lệ. 3. Nhập Email đúng định dạng. 4. Nhập Address hợp lệ. 5. Nhập Postcode theo quy tắc được hỗ trợ. 6. Thực hiện thao tác kích hoạt xác thực (ví dụ: rời focus khỏi trường hoặc thực hiện hành động tiếp tục/đặt hàng nếu có). | G3: B1: Nguyen B2: Van A B3: user@example.com B4: 123 Duong ABC, Quan 1 B5: 700000 | H3: 1. Giá trị được nhập và hiển thị trong trường First name. 2. Giá trị được nhập và hiển thị trong trường Last name. 3. Giá trị được nhập và hiển thị trong trường Email; không hiển thị lỗi định dạng email. 4. Giá trị được nhập và hiển thị trong trường Address. 5. Giá trị được nhập và hiển thị trong trường Postcode; không hiển thị lỗi định dạng postcode. 6. Không có thông báo lỗi cho bất kỳ trường nào khi tất cả dữ liệu hợp lệ. | I3: Đúng như kết quả mong đợi | J3: Pass
A4: 58 | B4: Thông tin địa chỉ thanh toán không hợp lệ | C4: Bỏ trống tất cả trường bắt buộc và kiểm tra thông báo lỗi | D4: Người dùng đang ở trang giỏ hàng; form địa chỉ thanh toán có thể chỉnh sửa; các trường đang trống. | E4: High | F4: 1. Đảm bảo tất cả trường First name, Last name, Email, Address, Postcode đang để trống. 2. Kích hoạt xác thực (ví dụ: rời focus khỏi từng trường hoặc thực hiện hành động tiếp tục/đặt hàng nếu có). | G4: — | H4: 1. Tất cả trường hiển thị trống. 2. Hệ thống hiển thị thông báo lỗi cho các trường bắt buộc bị bỏ trống. | I4: Đúng như kết quả mong đợi | J4: Pass
A5: 59 | B5: Thông tin địa chỉ thanh toán không hợp lệ | C5: Bỏ trống riêng trường First name và kiểm tra lỗi bắt buộc | D5: Người dùng đang ở trang giỏ hàng; form địa chỉ thanh toán có thể chỉnh sửa. | E5: High | F5: 1. Nhập Last name hợp lệ. 2. Nhập Email đúng định dạng. 3. Nhập Address hợp lệ. 4. Nhập Postcode theo quy tắc được hỗ trợ. 5. Để trống trường First name và kích hoạt xác thực. | G5: B1: Van A B2: user@example.com B3: 123 Duong ABC B4: 700000 | H5: 1. Last name được chấp nhận, không hiển thị lỗi. 2. Email được chấp nhận, không hiển thị lỗi định dạng. 3. Address được chấp nhận, không hiển thị lỗi. 4. Postcode được chấp nhận, không hiển thị lỗi định dạng. 5. Hệ thống hiển thị thông báo lỗi bắt buộc cho trường First name; các trường khác không bị báo lỗi. | I5: Đúng như kết quả mong đợi | J5: Pass
A6: 60 | B6: Thông tin địa chỉ thanh toán không hợp lệ | C6: Bỏ trống riêng trường Last name và kiểm tra lỗi bắt buộc | D6: Người dùng đang ở trang giỏ hàng; form địa chỉ thanh toán có thể chỉnh sửa. | E6: High | F6: 1. Nhập First name hợp lệ. 2. Nhập Email đúng định dạng. 3. Nhập Address hợp lệ. 4. Nhập Postcode theo quy tắc được hỗ trợ. 5. Để trống trường Last name và kích hoạt xác thực. | G6: B1: Nguyen B2: user@example.com B3: 123 Duong ABC B4: 700000 | H6: 1. First name được chấp nhận, không hiển thị lỗi. 2. Email được chấp nhận, không hiển thị lỗi định dạng. 3. Address được chấp nhận, không hiển thị lỗi. 4. Postcode được chấp nhận, không hiển thị lỗi định dạng. 5. Hệ thống hiển thị thông báo lỗi bắt buộc cho trường Last name; các trường khác không bị báo lỗi. | I6: Đúng như kết quả mong đợi | J6: Pass
A7: 61 | B7: Thông tin địa chỉ thanh toán không hợp lệ | C7: Bỏ trống riêng trường Email và kiểm tra lỗi bắt buộc | D7: Người dùng đang ở trang giỏ hàng; form địa chỉ thanh toán có thể chỉnh sửa. | E7: High | F7: 1. Nhập First name hợp lệ. 2. Nhập Last name hợp lệ. 3. Nhập Address hợp lệ. 4. Nhập Postcode theo quy tắc được hỗ trợ. 5. Để trống trường Email và kích hoạt xác thực. | G7: B1: Nguyen B2: Van A B3: 123 Duong ABC B4: 700000 | H7: 1. First name được chấp nhận, không hiển thị lỗi. 2. Last name được chấp nhận, không hiển thị lỗi. 3. Address được chấp nhận, không hiển thị lỗi. 4. Postcode được chấp nhận, không hiển thị lỗi định dạng. 5. Hệ thống hiển thị thông báo lỗi bắt buộc cho trường Email. | I7: Đúng như kết quả mong đợi | J7: Pass
A8: 62 | B8: Thông tin địa chỉ thanh toán không hợp lệ | C8: Nhập Email sai định dạng và kiểm tra thông báo lỗi | D8: Người dùng đang ở trang giỏ hàng; form địa chỉ thanh toán có thể chỉnh sửa. | E8: High | F8: 1. Nhập Email sai định dạng. 2. Kích hoạt xác thực cho trường Email (rời focus hoặc thực hiện hành động tiếp tục/đặt hàng nếu có). | G8: B1: userexample.com | H8: 1. Giá trị được nhập vào trường Email. 2. Hệ thống hiển thị thông báo lỗi do Email không đúng định dạng. | I8: không có thông báo lỗi và email sai định dạng vẫn được chấp nhận | J8: Fail | K8: BUG-03
A9: 63 | B9: Thông tin địa chỉ thanh toán không hợp lệ | C9: Nhập Email thiếu phần tên miền và kiểm tra lỗi định dạng | D9: Người dùng đang ở trang giỏ hàng; form địa chỉ thanh toán có thể chỉnh sửa. | E9: Medium | F9: 1. Nhập Email sai định dạng (thiếu tên miền hợp lệ). 2. Kích hoạt xác thực cho trường Email. | G9: B1: user@ | H9: 1. Giá trị được nhập vào trường Email. 2. Hệ thống hiển thị thông báo lỗi do Email không đúng định dạng. | I9: Không có thông báo lỗi và email sai định dạng vẫn được chấp nhận | J9: Fail | K9: BUG-04
A10: 64 | B10: Thông tin địa chỉ thanh toán không hợp lệ | C10: Nhập Postcode không khớp quy tắc được hỗ trợ và kiểm tra thông báo lỗi | D10: Người dùng đang ở trang giỏ hàng; form địa chỉ thanh toán có thể chỉnh sửa. | E10: High | F10: 1. Nhập Postcode không hợp lệ (không khớp quy tắc được hỗ trợ). 2. Kích hoạt xác thực cho trường Postcode (rời focus hoặc thực hiện hành động tiếp tục/đặt hàng nếu có). | G10: B1: INVALID | H10: 1. Giá trị được nhập vào trường Postcode. 2. Hệ thống hiển thị thông báo lỗi do Postcode không đúng định dạng/quy tắc được hỗ trợ. | I10: Đúng như kết quả mong đợi | J10: Pass
A11: 65 | B11: Thông tin địa chỉ thanh toán không hợp lệ | C11: Bỏ trống riêng trường Postcode và kiểm tra lỗi bắt buộc | D11: Người dùng đang ở trang giỏ hàng; form địa chỉ thanh toán có thể chỉnh sửa. | E11: High | F11: 1. Nhập First name hợp lệ. 2. Nhập Last name hợp lệ. 3. Nhập Email đúng định dạng. 4. Nhập Address hợp lệ. 5. Để trống trường Postcode và kích hoạt xác thực. | G11: B1: Nguyen B2: Van A B3: user@example.com B4: 123 Duong ABC | H11: 1. First name được chấp nhận, không hiển thị lỗi. 2. Last name được chấp nhận, không hiển thị lỗi. 3. Email được chấp nhận, không hiển thị lỗi định dạng. 4. Address được chấp nhận, không hiển thị lỗi. 5. Hệ thống hiển thị thông báo lỗi bắt buộc cho trường Postcode. | I11: Đúng như kết quả mong đợi | J11: Pass
A12: 66 | B12: Thông tin địa chỉ thanh toán không hợp lệ | C12: Bỏ trống riêng trường Address và kiểm tra lỗi bắt buộc | D12: Người dùng đang ở trang giỏ hàng; form địa chỉ thanh toán có thể chỉnh sửa. | E12: High | F12: 1. Nhập First name hợp lệ. 2. Nhập Last name hợp lệ. 3. Nhập Email đúng định dạng. 4. Nhập Postcode theo quy tắc được hỗ trợ. 5. Để trống trường Address và kích hoạt xác thực. | G12: B1: Nguyen B2: Van A B3: user@example.com B4: 700000 | H12: 1. First name được chấp nhận, không hiển thị lỗi. 2. Last name được chấp nhận, không hiển thị lỗi. 3. Email được chấp nhận, không hiển thị lỗi định dạng. 4. Postcode được chấp nhận, không hiển thị lỗi định dạng. 5. Hệ thống hiển thị thông báo lỗi bắt buộc cho trường Address. | I12: Đúng như kết quả mong đợi | J12: Pass
A13: 67 | B13: Thông tin địa chỉ thanh toán không hợp lệ | C13: Kết hợp lỗi: Email sai định dạng và Postcode sai quy tắc cùng lúc | D13: Người dùng đang ở trang giỏ hàng; form địa chỉ thanh toán có thể chỉnh sửa. | E13: High | F13: 1. Nhập First name hợp lệ. 2. Nhập Last name hợp lệ. 3. Nhập Address hợp lệ. 4. Nhập Email sai định dạng. 5. Nhập Postcode không khớp quy tắc được hỗ trợ. 6. Kích hoạt xác thực (rời focus hoặc thực hiện hành động tiếp tục/đặt hàng nếu có). | G13: B1: Nguyen B2: Van A B3: 123 Duong ABC B4: userexample.com B5: INVALID | H13: 1. First name được chấp nhận, không hiển thị lỗi. 2. Last name được chấp nhận, không hiển thị lỗi. 3. Address được chấp nhận, không hiển thị lỗi. 4. Email được nhập; chưa cần kết luận cho đến khi xác thực. 5. Postcode được nhập; chưa cần kết luận cho đến khi xác thực. 6. Hệ thống hiển thị thông báo lỗi cho cả Email (sai định dạng) và Postcode (không đúng quy tắc được hỗ trợ); các trường hợp lệ không bị báo lỗi. | I13: Không có thông báo lỗi và đơn hàng đặt thành công | J13: Fail | K13: BUG-05
A14: 68 | B14: Thông tin địa chỉ thanh toán không hợp lệ | C14: Sửa Email từ sai định dạng sang đúng định dạng và lỗi được gỡ bỏ | D14: Người dùng đang ở trang giỏ hàng; form địa chỉ thanh toán có thể chỉnh sửa. | E14: Medium | F14: 1. Nhập Email sai định dạng và kích hoạt xác thực. 2. Sửa Email sang đúng định dạng. 3. Kích hoạt xác thực lại cho trường Email. | G14: B1: userexample.com B2: user@example.com | H14: 1. Hệ thống hiển thị thông báo lỗi do Email không đúng định dạng. 2. Giá trị Email được cập nhật thành đúng định dạng. 3. Thông báo lỗi Email không còn hiển thị. | I14: Email sai định dạng được chấp nhận từ đầu | J14: Fail | K14: BUG-06
A15: 69 | B15: Thông tin địa chỉ thanh toán không hợp lệ | C15: Sửa Postcode từ không hợp lệ sang hợp lệ và lỗi được gỡ bỏ | D15: Người dùng đang ở trang giỏ hàng; form địa chỉ thanh toán có thể chỉnh sửa. | E15: Medium | F15: 1. Nhập Postcode không khớp quy tắc được hỗ trợ và kích hoạt xác thực. 2. Sửa Postcode sang giá trị hợp lệ theo quy tắc được hỗ trợ. 3. Kích hoạt xác thực lại cho trường Postcode. | G15: B1: INVALID B2: 700000 | H15: 1. Hệ thống hiển thị thông báo lỗi do Postcode không đúng định dạng/quy tắc được hỗ trợ. 2. Giá trị Postcode được cập nhật. 3. Thông báo lỗi Postcode không còn hiển thị. | I15: Postcode sai từ đầu nhưng vẫn được chấp nhận | J15: Fail | K15: BUG-07
A16: 70 | B16: Thông tin thanh toán hợp lệ | C16: Hiển thị đầy đủ các trường thanh toán với nhãn đúng | D16: Người dùng đang ở màn hình/biểu mẫu nhập thông tin thanh toán. | E16: High | F16: 1. Quan sát khu vực thông tin thanh toán trên UI. 2. Kiểm tra nhãn của từng trường thanh toán. | G16: — | H16: 1. Tất cả các trường thanh toán bắt buộc được hiển thị đầy đủ và rõ ràng. 2. Mỗi trường có nhãn đúng, không bị thiếu/nhầm lẫn, phù hợp với mục đích nhập liệu (tên chủ thẻ, số thẻ, ngày hết hạn, CVV). | I16: Đúng như kết quả mong đợi | J16: Pass
A17: 71 | B17: Thông tin thanh toán hợp lệ | C17: Thanh toán thành công với dữ liệu hợp lệ | D17: Người dùng đang ở màn hình thanh toán; hệ thống sẵn sàng xử lý giao dịch. | E17: High | F17: 1. Nhập tên chủ thẻ hợp lệ. 2. Nhập số thẻ tín dụng là số test hợp lệ. 3. Nhập ngày hết hạn ở tương lai theo đúng định dạng hệ thống yêu cầu. 4. Nhập CVV đúng định dạng. 5. Thực hiện hành động thanh toán/xác nhận giao dịch. | G17: B1: Tên chủ thẻ hợp lệ B2: Số thẻ test hợp lệ B3: Ngày hết hạn trong tương lai (đúng định dạng) B4: CVV đúng định dạng | H17: 1. Trường tên chủ thẻ chấp nhận dữ liệu, không hiển thị lỗi. 2. Trường số thẻ chấp nhận dữ liệu, không hiển thị lỗi. 3. Trường ngày hết hạn chấp nhận dữ liệu, không hiển thị lỗi. 4. Trường CVV chấp nhận dữ liệu, không hiển thị lỗi. 5. Hệ thống xử lý giao dịch thành công khi thông tin thanh toán hợp lệ. | I17: Đúng như kết quả mong đợi | J17: Pass
A18: 72 | B18: Thông tin thanh toán không hợp lệ | C18: Từ chối thanh toán khi thiếu tất cả trường bắt buộc | D18: Người dùng đang ở màn hình thanh toán; các trường đang trống. | E18: High | F18: 1. Không nhập dữ liệu vào bất kỳ trường nào. 2. Nhấn thanh toán/xác nhận giao dịch. | G18: — | H18: 1. Các trường vẫn trống, chưa có giao dịch được gửi. 2. Hệ thống từ chối thanh toán và hiển thị thông báo lỗi phù hợp cho các trường bắt buộc bị thiếu. | I18: Đúng như kết quả mong đợi | J18: Pass
A19: 73 | B19: Thông tin thanh toán không hợp lệ | C19: Từ chối thanh toán khi thiếu tên chủ thẻ | D19: Người dùng đang ở màn hình thanh toán. | E19: High | F19: 1. Để trống trường tên chủ thẻ. 2. Nhập số thẻ test hợp lệ. 3. Nhập ngày hết hạn trong tương lai (đúng định dạng). 4. Nhập CVV đúng định dạng. 5. Nhấn thanh toán/xác nhận giao dịch. | G19: B2: Số thẻ test hợp lệ B3: Ngày hết hạn trong tương lai (đúng định dạng) B4: CVV đúng định dạng | H19: 1. Trường tên chủ thẻ không có dữ liệu. 2. Trường số thẻ chấp nhận dữ liệu. 3. Trường ngày hết hạn chấp nhận dữ liệu. 4. Trường CVV chấp nhận dữ liệu. 5. Hệ thống từ chối thanh toán và hiển thị lỗi cho trường tên chủ thẻ bị thiếu. | I19: Đúng như kết quả mong đợi | J19: Pass
A20: 74 | B20: Thông tin thanh toán không hợp lệ | C20: Từ chối thanh toán khi thiếu số thẻ | D20: Người dùng đang ở màn hình thanh toán. | E20: High | F20: 1. Nhập tên chủ thẻ hợp lệ. 2. Để trống trường số thẻ. 3. Nhập ngày hết hạn trong tương lai (đúng định dạng). 4. Nhập CVV đúng định dạng. 5. Nhấn thanh toán/xác nhận giao dịch. | G20: B1: Tên chủ thẻ hợp lệ B3: Ngày hết hạn trong tương lai (đúng định dạng) B4: CVV đúng định dạng | H20: 1. Trường tên chủ thẻ chấp nhận dữ liệu. 2. Trường số thẻ không có dữ liệu. 3. Trường ngày hết hạn chấp nhận dữ liệu. 4. Trường CVV chấp nhận dữ liệu. 5. Hệ thống từ chối thanh toán và hiển thị lỗi cho trường số thẻ bị thiếu. | I20: Đúng như kết quả mong đợi | J20: Pass
A21: 75 | B21: Thông tin thanh toán không hợp lệ | C21: Từ chối thanh toán khi thiếu ngày hết hạn | D21: Người dùng đang ở màn hình thanh toán. | E21: High | F21: 1. Nhập tên chủ thẻ hợp lệ. 2. Nhập số thẻ test hợp lệ. 3. Để trống trường ngày hết hạn. 4. Nhập CVV đúng định dạng. 5. Nhấn thanh toán/xác nhận giao dịch. | G21: B1: Tên chủ thẻ hợp lệ B2: Số thẻ test hợp lệ B4: CVV đúng định dạng | H21: 1. Trường tên chủ thẻ chấp nhận dữ liệu. 2. Trường số thẻ chấp nhận dữ liệu. 3. Trường ngày hết hạn không có dữ liệu. 4. Trường CVV chấp nhận dữ liệu. 5. Hệ thống từ chối thanh toán và hiển thị lỗi cho trường ngày hết hạn bị thiếu. | I21: Đúng như kết quả mong đợi | J21: Pass
A22: 76 | B22: Thông tin thanh toán không hợp lệ | C22: Từ chối thanh toán khi thiếu CVV | D22: Người dùng đang ở màn hình thanh toán. | E22: High | F22: 1. Nhập tên chủ thẻ hợp lệ. 2. Nhập số thẻ test hợp lệ. 3. Nhập ngày hết hạn trong tương lai (đúng định dạng). 4. Để trống trường CVV. 5. Nhấn thanh toán/xác nhận giao dịch. | G22: B1: Tên chủ thẻ hợp lệ B2: Số thẻ test hợp lệ B3: Ngày hết hạn trong tương lai (đúng định dạng) | H22: 1. Trường tên chủ thẻ chấp nhận dữ liệu. 2. Trường số thẻ chấp nhận dữ liệu. 3. Trường ngày hết hạn chấp nhận dữ liệu. 4. Trường CVV không có dữ liệu. 5. Hệ thống từ chối thanh toán và hiển thị lỗi cho trường CVV bị thiếu. | I22: Đúng như kết quả mong đợi | J22: Pass
A23: 77 | B23: Thông tin thanh toán không hợp lệ | C23: Từ chối khi số thẻ chứa ký tự không được hỗ trợ | D23: Người dùng đang ở màn hình thanh toán. | E23: High | F23: 1. Nhập tên chủ thẻ hợp lệ. 2. Nhập số thẻ có chứa ký tự không được hỗ trợ. 3. Nhập ngày hết hạn trong tương lai (đúng định dạng). 4. Nhập CVV đúng định dạng. 5. Nhấn thanh toán/xác nhận giao dịch. | G23: B1: Tên chủ thẻ hợp lệ B2: Số thẻ có ký tự không được hỗ trợ B3: Ngày hết hạn trong tương lai (đúng định dạng) B4: CVV đúng định dạng | H23: 1. Trường tên chủ thẻ chấp nhận dữ liệu. 2. Hệ thống phát hiện dữ liệu không hợp lệ cho trường số thẻ và hiển thị thông báo lỗi phù hợp. 3. Trường ngày hết hạn chấp nhận dữ liệu. 4. Trường CVV chấp nhận dữ liệu. 5. Hệ thống từ chối thanh toán do số thẻ chứa ký tự không được hỗ trợ và hiển thị lỗi tương ứng. | I23: Số thẻ chứa chữ cái vẫn thanh toán thành công | J23: Fail | K23: BUG-08
A24: 78 | B24: Thông tin thanh toán không hợp lệ | C24: Từ chối khi số thẻ không phải số test hợp lệ | D24: Người dùng đang ở màn hình thanh toán. | E24: High | F24: 1. Nhập tên chủ thẻ hợp lệ. 2. Nhập số thẻ không phải số test hợp lệ. 3. Nhập ngày hết hạn trong tương lai (đúng định dạng). 4. Nhập CVV đúng định dạng. 5. Nhấn thanh toán/xác nhận giao dịch. | G24: B1: Tên chủ thẻ hợp lệ B2: Số thẻ không phải số test hợp lệ B3: Ngày hết hạn trong tương lai (đúng định dạng) B4: CVV đúng định dạng | H24: 1. Trường tên chủ thẻ chấp nhận dữ liệu. 2. Hệ thống phát hiện số thẻ không hợp lệ và hiển thị thông báo lỗi phù hợp. 3. Trường ngày hết hạn chấp nhận dữ liệu. 4. Trường CVV chấp nhận dữ liệu. 5. Hệ thống từ chối thanh toán do số thẻ không phải số test hợp lệ và hiển thị lỗi tương ứng. | I24: Số thẻ không hợp lệ vẫn đặt hàng thành công | J24: Fail | K24: BUG-09
A25: 79 | B25: Thông tin thanh toán không hợp lệ | C25: Từ chối khi ngày hết hạn sai định dạng | D25: Người dùng đang ở màn hình thanh toán. | E25: High | F25: 1. Nhập tên chủ thẻ hợp lệ. 2. Nhập số thẻ test hợp lệ. 3. Nhập ngày hết hạn sai định dạng. 4. Nhập CVV đúng định dạng. 5. Nhấn thanh toán/xác nhận giao dịch. | G25: B1: Tên chủ thẻ hợp lệ B2: Số thẻ test hợp lệ B3: Ngày hết hạn sai định dạng B4: CVV đúng định dạng | H25: 1. Trường tên chủ thẻ chấp nhận dữ liệu. 2. Trường số thẻ chấp nhận dữ liệu. 3. Hệ thống phát hiện định dạng ngày hết hạn không đúng và hiển thị thông báo lỗi phù hợp. 4. Trường CVV chấp nhận dữ liệu. 5. Hệ thống từ chối thanh toán do ngày hết hạn sai định dạng và hiển thị lỗi tương ứng. | I25: Hệ thống tạo đơn hàng thành công | J25: Fail | K25: BUG-10
A26: 80 | B26: Thông tin thanh toán không hợp lệ | C26: Từ chối khi ngày hết hạn là ngày trong quá khứ | D26: Người dùng đang ở màn hình thanh toán. | E26: High | F26: 1. Nhập tên chủ thẻ hợp lệ. 2. Nhập số thẻ test hợp lệ. 3. Nhập ngày hết hạn là ngày trong quá khứ (đúng định dạng). 4. Nhập CVV đúng định dạng. 5. Nhấn thanh toán/xác nhận giao dịch. | G26: B1: Tên chủ thẻ hợp lệ B2: Số thẻ test hợp lệ B3: Ngày hết hạn trong quá khứ (đúng định dạng) B4: CVV đúng định dạng | H26: 1. Trường tên chủ thẻ chấp nhận dữ liệu. 2. Trường số thẻ chấp nhận dữ liệu. 3. Hệ thống phát hiện ngày hết hạn không hợp lệ (đã qua) và hiển thị thông báo lỗi phù hợp. 4. Trường CVV chấp nhận dữ liệu. 5. Hệ thống từ chối thanh toán do ngày hết hạn trong quá khứ và hiển thị lỗi tương ứng. | I26: Hệ thống tạo đơn hàng thành công | J26: Fail | K26: BUG-11
A27: 81 | B27: Thông tin thanh toán không hợp lệ | C27: Chấp nhận khi ngày hết hạn là ngày trong tương lai | D27: Người dùng đang ở màn hình thanh toán. | E27: Medium | F27: 1. Nhập tên chủ thẻ hợp lệ. 2. Nhập số thẻ test hợp lệ. 3. Nhập ngày hết hạn trong tương lai (đúng định dạng). 4. Nhập CVV đúng định dạng. 5. Nhấn thanh toán/xác nhận giao dịch. | G27: B1: Tên chủ thẻ hợp lệ B2: Số thẻ test hợp lệ B3: Ngày hết hạn trong tương lai (đúng định dạng) B4: CVV đúng định dạng | H27: 1. Trường tên chủ thẻ chấp nhận dữ liệu. 2. Trường số thẻ chấp nhận dữ liệu. 3. Hệ thống chấp nhận ngày hết hạn và không hiển thị lỗi. 4. Trường CVV chấp nhận dữ liệu. 5. Hệ thống xử lý giao dịch thành công khi tất cả thông tin hợp lệ. | I27: Đúng như kết quả mong đợi | J27: Pass
A28: 82 | B28: Thông tin thanh toán không hợp lệ | C28: Từ chối khi CVV không hợp lệ | D28: Người dùng đang ở màn hình thanh toán. | E28: High | F28: 1. Nhập tên chủ thẻ hợp lệ. 2. Nhập số thẻ test hợp lệ. 3. Nhập ngày hết hạn trong tương lai (đúng định dạng). 4. Nhập CVV không hợp lệ. 5. Nhấn thanh toán/xác nhận giao dịch. | G28: B1: Tên chủ thẻ hợp lệ B2: Số thẻ test hợp lệ B3: Ngày hết hạn trong tương lai (đúng định dạng) B4: CVV không hợp lệ | H28: 1. Trường tên chủ thẻ chấp nhận dữ liệu. 2. Trường số thẻ chấp nhận dữ liệu. 3. Trường ngày hết hạn chấp nhận dữ liệu. 4. Hệ thống phát hiện CVV không hợp lệ và hiển thị thông báo lỗi phù hợp. 5. Hệ thống từ chối thanh toán do CVV không hợp lệ và hiển thị lỗi tương ứng. | I28: Hệ thống tạo đơn hàng thành công | J28: Fail | K28: BUG-12
A29: 83 | B29: Thông tin thanh toán không hợp lệ | C29: Từ chối khi tên chủ thẻ không hợp lệ | D29: Người dùng đang ở màn hình thanh toán. | E29: Medium | F29: 1. Nhập tên chủ thẻ không hợp lệ. 2. Nhập số thẻ test hợp lệ. 3. Nhập ngày hết hạn trong tương lai (đúng định dạng). 4. Nhập CVV đúng định dạng. 5. Nhấn thanh toán/xác nhận giao dịch. | G29: B1: Tên chủ thẻ không hợp lệ B2: Số thẻ test hợp lệ B3: Ngày hết hạn trong tương lai (đúng định dạng) B4: CVV đúng định dạng | H29: 1. Hệ thống phát hiện tên chủ thẻ không hợp lệ và hiển thị thông báo lỗi phù hợp. 2. Trường số thẻ chấp nhận dữ liệu. 3. Trường ngày hết hạn chấp nhận dữ liệu. 4. Trường CVV chấp nhận dữ liệu. 5. Hệ thống từ chối thanh toán do tên chủ thẻ không hợp lệ và hiển thị lỗi tương ứng. | I29: Hệ thống tạo đơn hàng thành công | J29: Fail | K29: BUG-13
A30: 84 | B30: Thông tin thanh toán không hợp lệ | C30: Hiển thị thông báo lỗi phù hợp cho nhiều lỗi đồng thời | D30: Người dùng đang ở màn hình thanh toán. | E30: Medium | F30: 1. Nhập tên chủ thẻ không hợp lệ. 2. Nhập số thẻ có ký tự không được hỗ trợ. 3. Nhập ngày hết hạn sai định dạng hoặc là ngày trong quá khứ. 4. Nhập CVV không hợp lệ. 5. Nhấn thanh toán/xác nhận giao dịch. | G30: B1: Tên chủ thẻ không hợp lệ B2: Số thẻ có ký tự không được hỗ trợ B3: Ngày hết hạn sai định dạng hoặc trong quá khứ B4: CVV không hợp lệ | H30: 1. Hệ thống có thể đánh dấu trường tên chủ thẻ không hợp lệ. 2. Hệ thống có thể đánh dấu trường số thẻ không hợp lệ. 3. Hệ thống có thể đánh dấu trường ngày hết hạn không hợp lệ. 4. Hệ thống có thể đánh dấu trường CVV không hợp lệ. 5. Hệ thống từ chối thanh toán và hiển thị các thông báo lỗi phù hợp tương ứng với từng trường sai/thiếu. | I30: Đúng như kết quả mong đợi | J30: Pass
A31: 85 | B31: Kiểm thử hiển thị và thao tác giỏ hàng hợp lệ | C31: Hiển thị đúng tên sản phẩm, số lượng và giá cho giỏ hàng có nhiều sản phẩm | D31: Người dùng đang ở màn hình giỏ hàng và giỏ hàng có nhiều sản phẩm đã được thêm trước đó. | E31: High | F31: 1. Mở màn hình giỏ hàng 2. Quan sát từng dòng sản phẩm trong danh sách | G31: — | H31: 1. Danh sách sản phẩm trong giỏ hàng được hiển thị. 2. Mỗi sản phẩm hiển thị đúng tên sản phẩm, số lượng và giá tương ứng. | I31: Đúng như kết quả mong đợi | J31: Pass
A32: 86 | B32: Kiểm thử hiển thị và thao tác giỏ hàng hợp lệ | C32: Tính tổng tiền chính xác dựa trên giá sản phẩm trong giỏ hàng | D32: Người dùng đang ở màn hình giỏ hàng và giỏ hàng có ít nhất 2 sản phẩm với giá hiển thị rõ ràng. | E32: High | F32: 1. Mở màn hình giỏ hàng 2. Ghi nhận giá của từng sản phẩm đang hiển thị trong giỏ hàng 3. Tính tổng tiền kỳ vọng bằng cách cộng giá của tất cả sản phẩm đang hiển thị 4. So sánh tổng tiền hiển thị trên UI với tổng tiền kỳ vọng | G32: — | H32: 1. Tổng tiền và danh sách sản phẩm được hiển thị. 2. Có thể đọc được giá của từng sản phẩm để đối chiếu. 3. Có được tổng tiền kỳ vọng bằng tổng giá các sản phẩm. 4. Tổng tiền hiển thị khớp với tổng tiền kỳ vọng. | I32: Đúng như kết quả mong đợi | J32: Pass
A33: 87 | B33: Kiểm thử hiển thị và thao tác giỏ hàng hợp lệ | C33: Cập nhật tổng tiền đúng sau khi xóa một sản phẩm khỏi giỏ hàng | D33: Người dùng đang ở màn hình giỏ hàng và giỏ hàng có nhiều sản phẩm; tổng tiền đang hiển thị. | E33: High | F33: 1. Ghi nhận tổng tiền hiện tại và danh sách sản phẩm đang có 2. Xóa một sản phẩm bất kỳ khỏi giỏ hàng bằng thao tác xóa trên UI 3. Tính tổng tiền kỳ vọng bằng cách cộng giá của các sản phẩm còn lại sau khi xóa 4. So sánh tổng tiền hiển thị sau khi xóa với tổng tiền kỳ vọng | G33: — | H33: 1. Tổng tiền hiện tại và các sản phẩm hiện có được ghi nhận để đối chiếu. 2. Sản phẩm được xóa khỏi danh sách hiển thị. 3. Tổng tiền kỳ vọng phản ánh tổng của các sản phẩm còn lại. 4. Tổng tiền hiển thị sau khi xóa khớp với tổng tiền kỳ vọng và phản ánh tổng của các sản phẩm còn lại. | I33: Đúng như kết quả mong đợi | J33: Pass
A34: 88 | B34: Kiểm thử hiển thị và thao tác giỏ hàng hợp lệ | C34: Không hiển thị sản phẩm đã bị xóa khỏi danh sách giỏ hàng | D34: Người dùng đang ở màn hình giỏ hàng và có ít nhất 1 sản phẩm trong giỏ hàng. | E34: Medium | F34: 1. Xác định một sản phẩm cụ thể đang hiển thị trong giỏ hàng 2. Thực hiện thao tác xóa sản phẩm mục tiêu khỏi giỏ hàng 3. Tải lại/refresh màn hình giỏ hàng (nếu có) hoặc quay lại rồi vào lại giỏ hàng | G34: — | H34: 1. Sản phẩm mục tiêu đang xuất hiện trong danh sách. 2. Sản phẩm mục tiêu biến mất khỏi danh sách giỏ hàng. 3. Sản phẩm đã xóa vẫn không xuất hiện lại trong danh sách. | I34: Đúng như kết quả mong đợi | J34: Pass
A35: 89 | B35: Kiểm thử hiển thị và thao tác giỏ hàng hợp lệ | C35: Xóa lần lượt tất cả sản phẩm: không còn sản phẩm nào được hiển thị | D35: Người dùng đang ở màn hình giỏ hàng và giỏ hàng có từ 1 sản phẩm trở lên. | E35: High | F35: 1. Thực hiện xóa từng sản phẩm trong giỏ hàng cho đến khi không còn sản phẩm nào 2. Quan sát danh sách sản phẩm sau khi đã xóa hết | G35: — | H35: 1. Sau mỗi lần xóa, sản phẩm tương ứng biến mất khỏi danh sách. 2. Không còn sản phẩm nào được hiển thị trong giỏ hàng. | I35: Đúng như kết quả mong đợi | J35: Pass
A36: 91 | B36: Kiểm thử hiển thị và thao tác giỏ hàng hợp lệ | C36: Sử dụng chức năng Empty Basket để xóa toàn bộ sản phẩm trong giỏ hàng | D36: Người dùng đang ở màn hình giỏ hàng và giỏ hàng có nhiều sản phẩm. | E36: High | F36: 1. Nhấn/Chọn chức năng Empty Basket trên UI 2. Quan sát danh sách sản phẩm sau khi Empty Basket 3. Quan sát trạng thái giỏ hàng | G36: — | H36: 1. Tất cả sản phẩm bị xóa khỏi giỏ hàng. 2. Không có sản phẩm nào được hiển thị. 3. Hệ thống hiển thị trạng thái phù hợp khi giỏ hàng trống. | I36: Đúng như kết quả mong đợi | J36: Pass
A37: 92 | B37: Kiểm thử hiển thị và thao tác giỏ hàng hợp lệ | C37: Tổng tiền phản ánh tổng của các sản phẩm còn lại sau khi Empty Basket | D37: Người dùng đang ở màn hình giỏ hàng và giỏ hàng có ít nhất 1 sản phẩm; tổng tiền đang hiển thị. | E37: High | F37: 1. Ghi nhận tổng tiền trước khi thực hiện Empty Basket 2. Thực hiện Empty Basket 3. Quan sát tổng tiền sau khi Empty Basket | G37: — | H37: 1. Tổng tiền trước khi xóa được ghi nhận. 2. Giỏ hàng được xóa toàn bộ sản phẩm. 3. Tổng tiền phản ánh trạng thái không còn sản phẩm trong giỏ hàng (không còn tổng của các sản phẩm đã bị xóa). | I37: Đúng như kết quả mong đợi | J37: Pass
A38: 90 | B38: Kiểm thử trạng thái giỏ hàng trống | C38: Hiển thị trạng thái phù hợp khi giỏ hàng trống sau khi xóa hết sản phẩm | D38: Người dùng đang ở màn hình giỏ hàng và giỏ hàng có ít nhất 1 sản phẩm. | E38: High | F38: 1. Xóa tất cả sản phẩm trong giỏ hàng 2. Quan sát khu vực trạng thái/thông báo của giỏ hàng | G38: — | H38: 1. Danh sách sản phẩm không còn hiển thị sản phẩm nào. 2. Hệ thống hiển thị trạng thái phù hợp cho giỏ hàng trống. | I38: Đúng như kết quả mong đợi | J38: Pass
A39: 93 | B39: Kiểm thử trạng thái giỏ hàng trống | C39: Giỏ hàng trống ngay từ đầu: hiển thị trạng thái phù hợp và không hiển thị sản phẩm | D39: Người dùng đang ở màn hình giỏ hàng và giỏ hàng đang trống (không có sản phẩm). | E39: Medium | F39: 1. Mở màn hình giỏ hàng khi giỏ hàng trống 2. Quan sát danh sách sản phẩm | G39: — | H39: 1. Hệ thống hiển thị trạng thái phù hợp cho giỏ hàng trống. 2. Không có sản phẩm nào được hiển thị trong danh sách. | I39: Đúng như kết quả mong đợi | J39: Pass
A40: 96 | B40: Kiểm thử lựa chọn phương thức giao hàng hợp lệ | C40: Mặc định phương thức giao hàng là Collect (FREE) | D40: Người dùng đang ở màn hình có lựa chọn phương thức giao hàng và hiển thị tổng tiền. | E40: High | F40: 1. Mở màn hình có lựa chọn phương thức giao hàng. 2. Quan sát phí vận chuyển và tổng tiền hiển thị. 3. Kiểm tra giá trị tổng tiền không hiển thị NaN. | G40: — | H40: 1. Collect (FREE) được chọn mặc định; Standard Shipping không được chọn. 2. Phí vận chuyển tương ứng Collect là FREE và tổng tiền không bao gồm phí £1.99. 3. Tổng tiền hiển thị là một giá trị hợp lệ, không phải NaN. | I40: Đúng như kết quả mong đợi | J40: Pass
...

Sheet Tổng hợp
A1: Tổng hợp kết quả test case – Sweet Shop
A3: Nhóm chức năng | B3: Tổng | C3: Pass | D3: Fail | E3: Tỷ lệ Pass
A4: Thông tin địa chỉ thanh toán hợp lệ | B4: =COUNTIF('Test case'!$B$2:$B$103,A4) -> 2 | C4: =COUNTIFS('Test case'!$B$2:$B$103,A4,'Test case'!$J$2:$J$103,"Pass") -> 2 | D4: =COUNTIFS('Test case'!$B$2:$B$103,A4,'Test case'!$J$2:$J$103,"Fail") -> 0 | E4: =IF(B4=0,0,C4/B4) -> 1
A5: Thông tin địa chỉ thanh toán không hợp lệ | B5: =COUNTIF('Test case'!$B$2:$B$103,A5) -> 12 | C5: =COUNTIFS('Test case'!$B$2:$B$103,A5,'Test case'!$J$2:$J$103,"Pass") -> 7 | D5: =COUNTIFS('Test case'!$B$2:$B$103,A5,'Test case'!$J$2:$J$103,"Fail") -> 5 | E5: =IF(B5=0,0,C5/B5) -> 0.58333333
A6: Thông tin thanh toán hợp lệ | B6: =COUNTIF('Test case'!$B$2:$B$103,A6) -> 2 | C6: =COUNTIFS('Test case'!$B$2:$B$103,A6,'Test case'!$J$2:$J$103,"Pass") -> 2 | D6: =COUNTIFS('Test case'!$B$2:$B$103,A6,'Test case'!$J$2:$J$103,"Fail") -> 0 | E6: =IF(B6=0,0,C6/B6) -> 1
A7: Thông tin thanh toán không hợp lệ | B7: =COUNTIF('Test case'!$B$2:$B$103,A7) -> 13 | C7: =COUNTIFS('Test case'!$B$2:$B$103,A7,'Test case'!$J$2:$J$103,"Pass") -> 7 | D7: =COUNTIFS('Test case'!$B$2:$B$103,A7,'Test case'!$J$2:$J$103,"Fail") -> 6 | E7: =IF(B7=0,0,C7/B7) -> 0.53846154
A8: Kiểm thử hiển thị và thao tác giỏ hàng hợp lệ | B8: =COUNTIF('Test case'!$B$2:$B$103,A8) -> 7 | C8: =COUNTIFS('Test case'!$B$2:$B$103,A8,'Test case'!$J$2:$J$103,"Pass") -> 7 | D8: =COUNTIFS('Test case'!$B$2:$B$103,A8,'Test case'!$J$2:$J$103,"Fail") -> 0 | E8: =IF(B8=0,0,C8/B8) -> 1
A9: Kiểm thử trạng thái giỏ hàng trống | B9: =COUNTIF('Test case'!$B$2:$B$103,A9) -> 2 | C9: =COUNTIFS('Test case'!$B$2:$B$103,A9,'Test case'!$J$2:$J$103,"Pass") -> 2 | D9: =COUNTIFS('Test case'!$B$2:$B$103,A9,'Test case'!$J$2:$J$103,"Fail") -> 0 | E9: =IF(B9=0,0,C9/B9) -> 1
A10: Kiểm thử lựa chọn phương thức giao hàng hợp lệ | B10: =COUNTIF('Test case'!$B$2:$B$103,A10) -> 5 | C10: =COUNTIFS('Test case'!$B$2:$B$103,A10,'Test case'!$J$2:$J$103,"Pass") -> 4 | D10: =COUNTIFS('Test case'!$B$2:$B$103,A10,'Test case'!$J$2:$J$103,"Fail") -> 1 | E10: =IF(B10=0,0,C10/B10) -> 0.8
A11: Kiểm thử lỗi tính tổng tiền khi áp dụng phí giao hàng | B11: =COUNTIF('Test case'!$B$2:$B$103,A11) -> 6 | C11: =COUNTIFS('Test case'!$B$2:$B$103,A11,'Test case'!$J$2:$J$103,"Pass") -> 3 | D11: =COUNTIFS('Test case'!$B$2:$B$103,A11,'Test case'!$J$2:$J$103,"Fail") -> 3 | E11: =IF(B11=0,0,C11/B11) -> 0.5
A12: Kiểm thử áp dụng mã khuyến mãi hợp lệ | B12: =COUNTIF('Test case'!$B$2:$B$103,A12) -> 2 | C12: =COUNTIFS('Test case'!$B$2:$B$103,A12,'Test case'!$J$2:$J$103,"Pass") -> 2 | D12: =COUNTIFS('Test case'!$B$2:$B$103,A12,'Test case'!$J$2:$J$103,"Fail") -> 0 | E12: =IF(B12=0,0,C12/B12) -> 1
A13: Kiểm thử áp dụng mã khuyến mãi không hợp lệ | B13: =COUNTIF('Test case'!$B$2:$B$103,A13) -> 9 | C13: =COUNTIFS('Test case'!$B$2:$B$103,A13,'Test case'!$J$2:$J$103,"Pass") -> 9 | D13: =COUNTIFS('Test case'!$B$2:$B$103,A13,'Test case'!$J$2:$J$103,"Fail") -> 0 | E13: =IF(B13=0,0,C13/B13) -> 1
A14: Kiểm thử xác nhận đơn hàng với thông tin hợp lệ | B14: =COUNTIF('Test case'!$B$2:$B$103,A14) -> 16 | C14: =COUNTIFS('Test case'!$B$2:$B$103,A14,'Test case'!$J$2:$J$103,"Pass") -> 14 | D14: =COUNTIFS('Test case'!$B$2:$B$103,A14,'Test case'!$J$2:$J$103,"Fail") -> 2 | E14: =IF(B14=0,0,C14/B14) -> 0.875
A15: Kiểm thử giao diện và trải nghiệm người dùng đúng thiết kế | B15: =COUNTIF('Test case'!$B$2:$B$103,A15) -> 17 | C15: =COUNTIFS('Test case'!$B$2:$B$103,A15,'Test case'!$J$2:$J$103,"Pass") -> 17 | D15: =COUNTIFS('Test case'!$B$2:$B$103,A15,'Test case'!$J$2:$J$103,"Fail") -> 0 | E15: =IF(B15=0,0,C15/B15) -> 1
... A17: Kiểm thử tính toàn vẹn dữ liệu giỏ hàng | B17: =COUNTIF('Test case'!$B$2:$B$103,A17) -> 1 | C17: =COUNTIFS('Test case'!$B$2:$B$103,A17,'Test case'!$J$2:$J$103,"Pass") -> 0 | D17: =COUNTIFS('Test case'!$B$2:$B$103,A17,'Test case'!$J$2:$J$103,"Fail") -> 1 | E17: =IF(B17=0,0,C17/B17) -> 0
A18: Tổng cộng | B18: =SUM(B4:B17) -> 102 | C18: =SUM(C4:C17) -> 84 | D18: =SUM(D4:D17) -> 18 | E18: =IF(B18=0,0,C18/B18) -> 0.82352941
